Workbook

Sheet Laporan
A1: LAPORAN PRODUKSI HARIAN
A2: Area: Water Treatment, Mixing Periode: Mar 2026
A5: PRODUKSI
A6: Stasiun | B6: Ukuran | C6: Shift | D6: Slot | E6: 02/03 | F6: 03/03 | G6: 04/03 | H6: 05/03 | I6: 06/03 | J6: 09/03 | K6: 10/03 | L6: 11/03 | M6: 12/03 | N6: 13/03 | O6: 16/03 | P6: 17/03 | Q6: 18/03 | R6: 19/03 | S6: 20/03 | T6: 23/03 | U6: 24/03 | V6: 25/03 | W6: 26/03 | X6: 27/03 | Y6: 30/03 | Z6: 31/03 | AA6: 01/04 | AB6: 02/04 | AC6: 03/04
A7: Water Treatment | B7: 330 ml | C7: Shift 1 | D7: 1 | E7: 3233 | F7: 3441 | G7: 3596 | H7: 2790 | I7: 3300 | J7: 3572 | K7: 2948 | L7: 3572 | M7: 3012 | N7: 3042 | O7: 3186 | P7: 3080 | Q7: 3527 | R7: 3177 | S7: 3085 | T7: 3402 | U7: 3278 | V7: 3198 | W7: 3159 | X7: 3381 | Y7: 3257 | Z7: 2895 | AA7: 3377 | AB7: 3596 | AC7: 3141
A8: Water Treatment | B8: 330 ml | C8: Shift 1 | D8: 2 | E8: 3411 | F8: 3236 | G8: 3517 | H8: 3438 | I8: 3720 | J8: 3255 | K8: 3633 | L8: 2775 | M8: 3360 | N8: 3224 | O8: 3106 | P8: 3417 | Q8: 3029 | R8: 3434 | S8: 3325 | T8: 3331 | U8: 3842 | V8: 3419 | W8: 3188 | X8: 3433 | Y8: 3216 | Z8: 2953 | AA8: 3078 | AB8: 3377 | AC8: 3091
A9: Water Treatment | B9: 330 ml | C9: Shift 1 | D9: 3 | E9: 3162 | F9: 3598 | G9: 3185 | H9: 3364 | I9: 2929 | J9: 2924 | K9: 3284 | L9: 2684 | M9: 3431 | N9: 3114 | O9: 3068 | P9: 3264 | Q9: 3414 | R9: 3167 | S9: 3203 | T9: 2746 | U9: 3179 | V9: 3310 | W9: 3719 | X9: 3265 | Y9: 3186 | Z9: 3124 | AA9: 3230 | AB9: 2984 | AC9: 3121
A10: Water Treatment | B10: 330 ml | C10: Shift 2 | D10: 1 | E10: 3283 | F10: 2851 | G10: 3167 | H10: 3146 | I10: 3318 | J10: 3423 | K10: 3143 | L10: 3037 | M10: 3097 | N10: 3585 | O10: 2752 | P10: 3141 | Q10: 3137 | R10: 3050 | S10: 3695 | T10: 3123 | U10: 3292 | V10: 3042 | W10: 3526 | X10: 2758 | Y10: 3196 | Z10: 2818 | AA10: 3507 | AB10: 2916 | AC10: 3145
A11: Water Treatment | B11: 330 ml | C11: Shift 2 | D11: 2 | E11: 3017 | F11: 3308 | G11: 2780 | H11: 3435 | I11: 3166 | J11: 3107 | K11: 3180 | L11: 3365 | M11: 3512 | N11: 2963 | O11: 3205 | P11: 3048 | Q11: 2965 | R11: 3161 | S11: 3231 | T11: 2949 | U11: 3153 | V11: 3022 | W11: 3264 | X11: 3205 | Y11: 3405 | Z11: 3027 | AA11: 3380 | AB11: 3063 | AC11: 3168
A12: Water Treatment | B12: 330 ml | C12: Shift 2 | D12: 3 | E12: 2860 | F12: 3031 | G12: 3191 | H12: 3194 | I12: 3560 | J12: 3116 | K12: 3348 | L12: 3039 | M12: 3047 | N12: 3196 | O12: - | P12: 3674 | Q12: 3484 | R12: 3446 | S12: 3155 | T12: 3586 | U12: 3074 | V12: 3422 | W12: 3176 | X12: 3615 | Y12: 3257 | Z12: 3077 | AA12: 3277 | AB12: 3460 | AC12: 2930
A13: Water Treatment | B13: 600 ml | C13: Shift 1 | D13: 1 | E13: 2820 | F13: 2607 | G13: 2633 | H13: 2858 | I13: 2679 | J13: 3126 | K13: 2795 | L13: 2740 | M13: 2645 | N13: 2972 | O13: 2571 | P13: 2592 | Q13: 2800 | R13: 2540 | S13: 2741 | T13: 2805 | U13: 2685 | V13: 3312 | W13: 2706 | X13: 2613 | Y13: 2715 | Z13: 2819 | AA13: 2893 | AB13: 2790 | AC13: 2837
A14: Water Treatment | B14: 600 ml | C14: Shift 1 | D14: 2 | E14: 2948 | F14: 2884 | G14: 2826 | H14: - | I14: 2908 | J14: 2875 | K14: 2314 | L14: 3001 | M14: 2856 | N14: 3235 | O14: 2388 | P14: 2717 | Q14: 2927 | R14: 2968 | S14: 2780 | T14: 2914 | U14: 3064 | V14: 3024 | W14: 2537 | X14: 2621 | Y14: 2815 | Z14: 2829 | AA14: 2663 | AB14: 2991 | AC14: 2736
A15: Water Treatment | B15: 600 ml | C15: Shift 1 | D15: 3 | E15: 2783 | F15: 2834 | G15: 2555 | H15: 2784 | I15: 3058 | J15: 3071 | K15: 2799 | L15: 2981 | M15: 2708 | N15: 2561 | O15: 2771 | P15: 2371 | Q15: 2783 | R15: 2908 | S15: 2858 | T15: 2551 | U15: 2883 | V15: 3185 | W15: 2851 | X15: 2887 | Y15: 2596 | Z15: 2729 | AA15: 2618 | AB15: 2542 | AC15: 2605
A16: Water Treatment | B16: 600 ml | C16: Shift 2 | D16: 1 | E16: 2968 | F16: 2311 | G16: 3081 | H16: 2324 | I16: 2308 | J16: 2460 | K16: 2763 | L16: 2809 | M16: 2619 | N16: 3117 | O16: 2731 | P16: 2894 | Q16: 2615 | R16: 3234 | S16: 2669 | T16: 2518 | U16: 3011 | V16: 2908 | W16: 2417 | X16: 2682 | Y16: 2659 | Z16: 2755 | AA16: 3063 | AB16: 2775 | AC16: 2940
A17: Water Treatment | B17: 600 ml | C17: Shift 2 | D17: 2 | E17: 2886 | F17: 3225 | G17: 2913 | H17: 2774 | I17: 2765 | J17: 2892 | K17: 3144 | L17: 2880 | M17: 3122 | N17: 3228 | O17: 2378 | P17: 2579 | Q17: 2662 | R17: 3246 | S17: 2763 | T17: 2748 | U17: 3058 | V17: 2847 | W17: 2677 | X17: 2899 | Y17: 3021 | Z17: 3010 | AA17: 2824 | AB17: 2627 | AC17: 2619
A18: Water Treatment | B18: 600 ml | C18: Shift 2 | D18: 3 | E18: 3095 | F18: 2803 | G18: 2949 | H18: 2945 | I18: 3072 | J18: 2475 | K18: 2843 | L18: 2875 | M18: 2905 | N18: 2866 | O18: 2719 | P18: 2642 | Q18: 3094 | R18: 3256 | S18: 2881 | T18: 3439 | U18: 2786 | V18: 2323 | W18: 2848 | X18: 2935 | Y18: 2634 | Z18: 2578 | AA18: 2560 | AB18: 3006 | AC18: 2842
A19: Water Treatment | B19: 1,5 L | C19: Shift 1 | D19: 1 | E19: 1523 | F19: 1379 | G19: 1495 | H19: 1539 | I19: 1540 | J19: 1331 | K19: 1439 | L19: 1767 | M19: 1549 | N19: 1509 | O19: 1588 | P19: 1539 | Q19: 1522 | R19: 1597 | S19: 1580 | T19: 1453 | U19: 1496 | V19: 1573 | W19: 1458 | X19: 1619 | Y19: 1475 | Z19: 1544 | AA19: 1493 | AB19: 1497 | AC19: 1539
A20: Water Treatment | B20: 1,5 L | C20: Shift 1 | D20: 2 | E20: 1560 | F20: 1520 | G20: 1429 | H20: 1579 | I20: 1548 | J20: 1524 | K20: 1481 | L20: 1448 | M20: 1502 | N20: 1439 | O20: 1355 | P20: 1509 | Q20: 1580 | R20: 1769 | S20: 1634 | T20: 1407 | U20: 1513 | V20: 1553 | W20: 1590 | X20: 1433 | Y20: 1522 | Z20: 1620 | AA20: 1376 | AB20: 1563 | AC20: 1469
A21: Water Treatment | B21: 1,5 L | C21: Shift 1 | D21: 3 | E21: 1615 | F21: 1474 | G21: 1501 | H21: 1490 | I21: 1360 | J21: 1605 | K21: 1543 | L21: 1636 | M21: 1368 | N21: 1626 | O21: 1454 | P21: 1506 | Q21: 1368 | R21: 1427 | S21: 1783 | T21: 1391 | U21: 1524 | V21: 1509 | W21: 1566 | X21: 1646 | Y21: 1672 | Z21: 1309 | AA21: 1534 | AB21: 1410 | AC21: 1360
A22: Water Treatment | B22: 1,5 L | C22: Shift 2 | D22: 1 | E22: 1639 | F22: 1574 | G22: 1503 | H22: 1479 | I22: 1481 | J22: 1552 | K22: 1638 | L22: 1546 | M22: 1656 | N22: 1425 | O22: 1419 | P22: 1624 | Q22: 1452 | R22: 1351 | S22: 1377 | T22: 1507 | U22: 1387 | V22: 1450 | W22: 1675 | X22: 1416 | Y22: 1323 | Z22: 1440 | AA22: 1321 | AB22: 1515 | AC22: 1387
A23: Water Treatment | B23: 1,5 L | C23: Shift 2 | D23: 2 | E23: 1337 | F23: 1443 | G23: 1557 | H23: 1589 | I23: 1463 | J23: 1617 | K23: n/a | L23: 1549 | M23: 1582 | N23: 1453 | O23: 1503 | P23: 1625 | Q23: 1517 | R23: 1590 | S23: 1619 | T23: 1621 | U23: 1595 | V23: 1398 | W23: 1394 | X23: 1433 | Y23: 1666 | Z23: 1589 | AA23: 1543 btl | AB23: 1535 | AC23: 1721
A24: Water Treatment | B24: 1,5 L | C24: Shift 2 | D24: 3 | E24: 1641 | F24: 1498 | G24: 1357 | H24: 1423 | I24: 1480 | J24: 1563 | K24: 1538 | L24: 1546 | M24: 1526 | N24: 1497 | O24: 1432 | P24: 1533 | Q24: 1547 | R24: 1585 | S24: 1407 | T24: 1440 | U24: 1507 | V24: 1494 | W24: 1457 | X24: 1613 | Y24: 1429 | Z24: 1612 | AA24: 1347 | AB24: 1526 | AC24: 1698
A25: Mixing | B25: 330 ml | C25: Shift 1 | D25: 1 | E25: 3342 | F25: 3168 | G25: 3660 | H25: 3373 | I25: 3118 | J25: 3245 | K25: 3140 | L25: 2931 | M25: 3059 | N25: 3008 | O25: n/a | P25: 3010 | Q25: 3244 | R25: 2535 | S25: 3203 | T25: 3043 | U25: 2982 | V25: 3581 | W25: 3539 | X25: 2785 | Y25: 3103 | Z25: 3226 | AA25: 3219 | AB25: 3358 | AC25: 3096
A26: Mixing | B26: 330 ml | C26: Shift 1 | D26: 2 | E26: 3319 | F26: 2826 | G26: 3342 | H26: 2770 | I26: 3256 | J26: 3631 | K26: 2767 | L26: 3274 | M26: 3393 | N26: 3103 | O26: 3213 | P26: 3134 | Q26: 3123 | R26: 3152 | S26: 3443 | T26: 2943 | U26: 2942 | V26: 3495 | W26: 3276 | X26: 2975 | Y26: 3137 | Z26: 3011 | AA26: 3031 | AB26: 3493 | AC26: 3149
A27: Mixing | B27: 330 ml | C27: Shift 1 | D27: 3 | E27: 2927 | F27: 3077 | G27: 3396 | H27: 2917 | I27: 3119 | J27: 2821 | K27: 3406 | L27: 3458 | M27: 3087 | N27: 2920 | O27: 3188 | P27: 3255 | Q27: 3507 | R27: 3208 | S27: 3200 | T27: 3036 | U27: 3317 | V27: 3075 | W27: 3245 | X27: 3117 | Y27: 3457 | Z27: 3102 | AA27: 3336 | AB27: 3193 | AC27: 3087
A28: Mixing | B28: 330 ml | C28: Shift 2 | D28: 1 | E28: 3191 | F28: 3133 | G28: 3063 | H28: 3844 | I28: 3495 btl | J28: 3129 | K28: 3154 | L28: 3286 | M28: 3013 | N28: 3359 | O28: 3448 | P28: 2664 | Q28: 3074 | R28: 3661 | S28: 3197 | T28: 3237 | U28: 3167 | V28: 2946 | W28: 3126 | X28: 28150 | Y28: 3299 | Z28: 2909 | AA28: 3434 | AB28: 3245 | AC28: 2987
A29: Mixing | B29: 330 ml | C29: Shift 2 | D29: 2 | E29: 3385 | F29: 3585 | G29: 3455 | H29: 3413 | I29: 3264 | J29: 3167 | K29: 3262 | L29: 3378 | M29: 3211 | N29: 2828 | O29: 3002 | P29: 3083 | Q29: 3513 | R29: 2964 | S29: 3190 | T29: 2901 | U29: 2674 | V29: 3257 | W29: 3249 | X29: 3397 | Y29: 2801 | Z29: 3246 | AA29: 2724 | AB29: 3425 | AC29: 3010
A30: Mixing | B30: 330 ml | C30: Shift 2 | D30: 3 | E30: 3569 | F30: 3200 | G30: 2842 | H30: 3498 | I30: 2885 | J30: 3319 | K30: 3292 | L30: 3336 | M30: 3328 | N30: 3582 | O30: 3126 | P30: 2881 | Q30: n/a | R30: 3168 | S30: 3135 | T30: 3058 | U30: 3353 | V30: 3374 | W30: 3235 | X30: 3481 | Y30: 3114 | Z30: 3183 | AA30: 2928 | AB30: 3151 | AC30: 3340
A31: Mixing | B31: 600 ml | C31: Shift 1 | D31: 1 | E31: 2913 | F31: 2872 | G31: 2638 | H31: 3068 | I31: 2967 | J31: 2767 | K31: 2809 | L31: 2716 | M31: 2844 | N31: 2546 | O31: 2745 | P31: 2496 | Q31: 2658 | R31: 2806 | S31: 2724 | T31: 2776 | U31: 2671 | V31: 2522 | W31: 2781 | X31: 3162 | Y31: 2948 | Z31: 2886 | AA31: 3114 | AB31: 2455 | AC31: 2503
A32: Mixing | B32: 600 ml | C32: Shift 1 | D32: 2 | E32: 2911 | F32: 3060 | G32: 2799 | H32: 2989 | I32: 2789 | J32: 3444 | K32: 2832 | L32: n/a | M32: 2838 | N32: 3073 | O32: 2747 | P32: 2680 | Q32: 3182 | R32: 2575 | S32: 2953 | T32: 2932 | U32: 2766 | V32: 2882 | W32: 2847 | X32: 2765 | Y32: 2754 | Z32: 2772 | AA32: 2956 | AB32: 2715 | AC32: 3191
A33: Mixing | B33: 600 ml | C33: Shift 1 | D33: 3 | E33: 2994 | F33: 3084 | G33: 2937 | H33: 2776 | I33: 2480 | J33: 2930 | K33: 2795 | L33: 2857 | M33: 2621 | N33: 2740 | O33: 2810 | P33: 2640 | Q33: 3088 | R33: 2799 | S33: 2810 | T33: 2838 | U33: 2967 | V33: 2536 | W33: 2841 | X33: 2944 | Y33: 2786 | Z33: 2931 | AA33: n/a | AB33: 3081 | AC33: 2458
A34: Mixing | B34: 600 ml | C34: Shift 2 | D34: 1 | E34: 2679 | F34: 2739 | G34: 3047 | H34: 2649 | I34: 2428 | J34: 2786 | K34: 2575 | L34: 2757 | M34: 2933 | N34: 2894 | O34: 2836 | P34: 2570 | Q34: 3356 | R34: 2774 | S34: 2494 | T34: 2625 | U34: 2770 | V34: 2441 | W34: 2627 | X34: 2481 | Y34: 2583 | Z34: 2767 | AA34: 2772 | AB34: 3127 | AC34: 2961
A35: Mixing | B35: 600 ml | C35: Shift 2 | D35: 2 | E35: 2725 | F35: 2996 | G35: 2953 | H35: 2452 | I35: 2516 | J35: 2828 | K35: 2814 | L35: 3031 | M35: - | N35: 2634 | O35: 2692 | P35: 2503 | Q35: 2877 | R35: 2678 | S35: 2684 | T35: 2814 | U35: 2825 | V35: 2828 | W35: 3010 | X35: 3108 | Y35: 2541 | Z35: 2715 | AA35: 2816 | AB35: 2851 | AC35: 2774
A36: Mixing | B36: 600 ml | C36: Shift 2 | D36: 3 | E36: 2504 | F36: 3033 | G36: 2435 | H36: 2530 | I36: 3173 | J36: 2965 | K36: 2984 | L36: 2684 | M36: 2985 | N36: 2972 | O36: 3016 | P36: 3069 | Q36: 3008 | R36: 2848 | S36: 3106 | T36: 3068 | U36: 2564 | V36: 2614 | W36: 2874 | X36: 3120 | Y36: 2670 | Z36: 2653 | AA36: 2494 | AB36: 2924 | AC36: 2836
A37: Mixing | B37: 1,5 L | C37: Shift 1 | D37: 1 | E37: - | F37: 1358 | G37: 13250 | H37: 1348 | I37: 1466 | J37: 1437 | K37: 1460 | L37: 1503 | M37: 1468 | N37: 1452 | O37: 1557 | P37: 1627 | Q37: 1383 | R37: 1593 | S37: 1598 | T37: 1518 | U37: 15340 | V37: 1518 | W37: 1394 | X37: 1636 | Y37: 1469 | Z37: 1490 | AA37: 1472 | AB37: 1650 | AC37: 1401
A38: Mixing | B38: 1,5 L | C38: Shift 1 | D38: 2 | E38: 1503 | F38: 1445 | G38: 1615 | H38: 1468 | I38: 1403 | J38: 1609 | K38: 1547 | L38: 1612 | M38: 1720 | N38: 1559 | O38: 1408 | P38: 1510 | Q38: 1555 | R38: 1550 | S38: 1538 | T38: 1439 | U38: 1561 | V38: 1520 | W38: 1661 | X38: 1515 | Y38: 1473 | Z38: 1679 | AA38: 1449 | AB38: 1439 | AC38: 1457
A39: Mixing | B39: 1,5 L | C39: Shift 1 | D39: 3 | E39: 1675 | F39: 1387 | G39: 1357 | H39: 1322 | I39: 1513 | J39: 1522 | K39: 1485 | L39: 1663 | M39: 1400 | N39: 1373 | O39: 1285 | P39: 1450 | Q39: 1613 | R39: 1584 | S39: 1508 btl | T39: 1361 | U39: n/a | V39: 1462 | W39: 1374 | X39: 1530 | Y39: 1515 | Z39: 1611 | AA39: 1439 | AB39: 1570 | AC39: 1413
A40: Mixing | B40: 1,5 L | C40: Shift 2 | D40: 1 | E40: 1535 | F40: 1515 | G40: 1504 | H40: 1516 | I40: 1424 | J40: 1392 | K40: 1388 | L40: 1593 | M40: 1607 | N40: 1471 | O40: 1394 | P40: 1456 | Q40: 1487 | R40: 1759 | S40: 1666 | T40: 1428 | U40: 1656 | V40: 1765 | W40: 1703 | X40: 1342 | Y40: 1367 | Z40: 1668 | AA40: 1481 | AB40: 1382 | AC40: 1255
A41: Mixing | B41: 1,5 L | C41: Shift 2 | D41: 2 | E41: 1424 | F41: 1537 | G41: 1354 | H41: 1652 | I41: 1620 | J41: 1465 | K41: 1267 | L41: 1457 | M41: 1556 | N41: 1438 | O41: 1508 | P41: 1457 | Q41: 1388 | R41: 1501 | S41: 1483 | T41: 1468 | U41: 1428 | V41: 1635 | W41: 1446 | X41: 1714 | Y41: 1497 | Z41: 1656 | AA41: 1575 | AB41: 1449 | AC41: 1417
A42: Mixing | B42: 1,5 L | C42: Shift 2 | D42: 3 | E42: 1508 | F42: 1315 | G42: 1582 | H42: 1474 | I42: 1396 | J42: 1685 | K42: 1433 | L42: 1651 | M42: 1352 | N42: 1299 | O42: 1580 | P42: 1524 | Q42: 1463 | R42: 1609 | S42: 1401 | T42: 1375 | U42: 1537 | V42: 1399 | W42: 1397 | X42: 1498 | Y42: 1404 | Z42: 1487 | AA42: 1434 | AB42: 1250 | AC42: 1565
...

Sheet Pemetaan
A1: Tahun laporan | B1: 2026
A2: Kolom pertama nilai (nomor kolom) | B2: 5
A3: Baris data per blok | B3: 36
A4: Jumlah tanggal | B4: 25
A5: Baris penanda PRODUKSI | B5: =MATCH("PRODUKSI",Laporan!$A:$A,0) -> 5
A6: Baris penanda REJECT | B6: =MATCH("REJECT",Laporan!$A:$A,0) -> 46

Sheet Tidy
A1: k | B1: blok | C1: urut | D1: baris_ke | E1: kolom_ke | F1: baris_penanda | G1: baris_sumber | H1: kolom_sumber | I1: station | J1: size | K1: shift | L1: slot | M1: date | N1: mentah | O1: value | P1: metric
A2: 1 | B2: =IF(A2<=36*25,"PRODUKSI","REJECT") -> PRODUKSI | C2: =MOD(A2-1,Pemetaan!$B$3*Pemetaan!$B$4) -> 0 | D2: =INT(C2/Pemetaan!$B$4) -> 0 | E2: =MOD(C2,Pemetaan!$B$4) -> 0 | F2: =IF(B2="PRODUKSI",Pemetaan!$B$5,Pemetaan!$B$6) -> 5 | G2: =F2+2+D2 -> 7 | H2: =Pemetaan!$B$2+E2 -> 5 | I2: =INDEX(Laporan!$A$1:$AZ$300,G2,1) -> Water Treatment | J2: =INDEX(Laporan!$A$1:$AZ$300,G2,2) -> 330 ml | K2: =INDEX(Laporan!$A$1:$AZ$300,G2,3) -> Shift 1 | L2: =INDEX(Laporan!$A$1:$AZ$300,G2,4) -> 1 | M2: =DATE(Pemetaan!$B$1,VALUE(RIGHT(INDEX(Laporan!$A$1:$AZ$300,F2+1,H2),2)),VALUE(LEFT(INDEX(Laporan!$A$1:$AZ$300,F2+1,H2),2))) -> 46083 | N2: =INDEX(Laporan!$A$1:$AZ$300,G2,H2) -> 3233 | O2: =IF(N2="","",IFERROR(VALUE(SUBSTITUTE(SUBSTITUTE(N2," btl",""),".","")),"")) -> 3233 | P2: =IF(B2="PRODUKSI","produced","reject") -> produced
A3: 2 | B3: =IF(A3<=36*25,"PRODUKSI","REJECT") -> PRODUKSI | C3: =MOD(A3-1,Pemetaan!$B$3*Pemetaan!$B$4) -> 1 | D3: =INT(C3/Pemetaan!$B$4) -> 0 | E3: =MOD(C3,Pemetaan!$B$4) -> 1 | F3: =IF(B3="PRODUKSI",Pemetaan!$B$5,Pemetaan!$B$6) -> 5 | G3: =F3+2+D3 -> 7 | H3: =Pemetaan!$B$2+E3 -> 6 | I3: =INDEX(Laporan!$A$1:$AZ$300,G3,1) -> Water Treatment | J3: =INDEX(Laporan!$A$1:$AZ$300,G3,2) -> 330 ml | K3: =INDEX(Laporan!$A$1:$AZ$300,G3,3) -> Shift 1 | L3: =INDEX(Laporan!$A$1:$AZ$300,G3,4) -> 1 | M3: =DATE(Pemetaan!$B$1,VALUE(RIGHT(INDEX(Laporan!$A$1:$AZ$300,F3+1,H3),2)),VALUE(LEFT(INDEX(Laporan!$A$1:$AZ$300,F3+1,H3),2))) -> 46084 | N3: =INDEX(Laporan!$A$1:$AZ$300,G3,H3) -> 3441 | O3: =IF(N3="","",IFERROR(VALUE(SUBSTITUTE(SUBSTITUTE(N3," btl",""),".","")),"")) -> 3441 | P3: =IF(B3="PRODUKSI","produced","reject") -> produced
A4: 3 | B4: =IF(A4<=36*25,"PRODUKSI","REJECT") -> PRODUKSI | C4: =MOD(A4-1,Pemetaan!$B$3*Pemetaan!$B$4) -> 2 | D4: =INT(C4/Pemetaan!$B$4) -> 0 | E4: =MOD(C4,Pemetaan!$B$4) -> 2 | F4: =IF(B4="PRODUKSI",Pemetaan!$B$5,Pemetaan!$B$6) -> 5 | G4: =F4+2+D4 -> 7 | H4: =Pemetaan!$B$2+E4 -> 7 | I4: =INDEX(Laporan!$A$1:$AZ$300,G4,1) -> Water Treatment | J4: =INDEX(Laporan!$A$1:$AZ$300,G4,2) -> 330 ml | K4: =INDEX(Laporan!$A$1:$AZ$300,G4,3) -> Shift 1 | L4: =INDEX(Laporan!$A$1:$AZ$300,G4,4) -> 1 | M4: =DATE(Pemetaan!$B$1,VALUE(RIGHT(INDEX(Laporan!$A$1:$AZ$300,F4+1,H4),2)),VALUE(LEFT(INDEX(Laporan!$A$1:$AZ$300,F4+1,H4),2))) -> 46085 | N4: =INDEX(Laporan!$A$1:$AZ$300,G4,H4) -> 3596 | O4: =IF(N4="","",IFERROR(VALUE(SUBSTITUTE(SUBSTITUTE(N4," btl",""),".","")),"")) -> 3596 | P4: =IF(B4="PRODUKSI","produced","reject") -> produced
A5: 4 | B5: =IF(A5<=36*25,"PRODUKSI","REJECT") -> PRODUKSI | C5: =MOD(A5-1,Pemetaan!$B$3*Pemetaan!$B$4) -> 3 | D5: =INT(C5/Pemetaan!$B$4) -> 0 | E5: =MOD(C5,Pemetaan!$B$4) -> 3 | F5: =IF(B5="PRODUKSI",Pemetaan!$B$5,Pemetaan!$B$6) -> 5 | G5: =F5+2+D5 -> 7 | H5: =Pemetaan!$B$2+E5 -> 8 | I5: =INDEX(Laporan!$A$1:$AZ$300,G5,1) -> Water Treatment | J5: =INDEX(Laporan!$A$1:$AZ$300,G5,2) -> 330 ml | K5: =INDEX(Laporan!$A$1:$AZ$300,G5,3) -> Shift 1 | L5: =INDEX(Laporan!$A$1:$AZ$300,G5,4) -> 1 | M5: =DATE(Pemetaan!$B$1,VALUE(RIGHT(INDEX(Laporan!$A$1:$AZ$300,F5+1,H5),2)),VALUE(LEFT(INDEX(Laporan!$A$1:$AZ$300,F5+1,H5),2))) -> 46086 | N5: =INDEX(Laporan!$A$1:$AZ$300,G5,H5) -> 2790 | O5: =IF(N5="","",IFERROR(VALUE(SUBSTITUTE(SUBSTITUTE(N5," btl",""),".","")),"")) -> 2790 | P5: =IF(B5="PRODUKSI","produced","reject") -> produced
A6: 5 | B6: =IF(A6<=36*25,"PRODUKSI","REJECT") -> PRODUKSI | C6: =MOD(A6-1,Pemetaan!$B$3*Pemetaan!$B$4) -> 4 | D6: =INT(C6/Pemetaan!$B$4) -> 0 | E6: =MOD(C6,Pemetaan!$B$4) -> 4 | F6: =IF(B6="PRODUKSI",Pemetaan!$B$5,Pemetaan!$B$6) -> 5 | G6: =F6+2+D6 -> 7 | H6: =Pemetaan!$B$2+E6 -> 9 | I6: =INDEX(Laporan!$A$1:$AZ$300,G6,1) -> Water Treatment | J6: =INDEX(Laporan!$A$1:$AZ$300,G6,2) -> 330 ml | K6: =INDEX(Laporan!$A$1:$AZ$300,G6,3) -> Shift 1 | L6: =INDEX(Laporan!$A$1:$AZ$300,G6,4) -> 1 | M6: =DATE(Pemetaan!$B$1,VALUE(RIGHT(INDEX(Laporan!$A$1:$AZ$300,F6+1,H6),2)),VALUE(LEFT(INDEX(Laporan!$A$1:$AZ$300,F6+1,H6),2))) -> 46087 | N6: =INDEX(Laporan!$A$1:$AZ$300,G6,H6) -> 3300 | O6: =IF(N6="","",IFERROR(VALUE(SUBSTITUTE(SUBSTITUTE(N6," btl",""),".","")),"")) -> 3300 | P6: =IF(B6="PRODUKSI","produced","reject") -> produced
A7: 6 | B7: =IF(A7<=36*25,"PRODUKSI","REJECT") -> PRODUKSI | C7: =MOD(A7-1,Pemetaan!$B$3*Pemetaan!$B$4) -> 5 | D7: =INT(C7/Pemetaan!$B$4) -> 0 | E7: =MOD(C7,Pemetaan!$B$4) -> 5 | F7: =IF(B7="PRODUKSI",Pemetaan!$B$5,Pemetaan!$B$6) -> 5 | G7: =F7+2+D7 -> 7 | H7: =Pemetaan!$B$2+E7 -> 10 | I7: =INDEX(Laporan!$A$1:$AZ$300,G7,1) -> Water Treatment | J7: =INDEX(Laporan!$A$1:$AZ$300,G7,2) -> 330 ml | K7: =INDEX(Laporan!$A$1:$AZ$300,G7,3) -> Shift 1 | L7: =INDEX(Laporan!$A$1:$AZ$300,G7,4) -> 1 | M7: =DATE(Pemetaan!$B$1,VALUE(RIGHT(INDEX(Laporan!$A$1:$AZ$300,F7+1,H7),2)),VALUE(LEFT(INDEX(Laporan!$A$1:$AZ$300,F7+1,H7),2))) -> 46090 | N7: =INDEX(Laporan!$A$1:$AZ$300,G7,H7) -> 3572 | O7: =IF(N7="","",IFERROR(VALUE(SUBSTITUTE(SUBSTITUTE(N7," btl",""),".","")),"")) -> 3572 | P7: =IF(B7="PRODUKSI","produced","reject") -> produced
A8: 7 | B8: =IF(A8<=36*25,"PRODUKSI","REJECT") -> PRODUKSI | C8: =MOD(A8-1,Pemetaan!$B$3*Pemetaan!$B$4) -> 6 | D8: =INT(C8/Pemetaan!$B$4) -> 0 | E8: =MOD(C8,Pemetaan!$B$4) -> 6 | F8: =IF(B8="PRODUKSI",Pemetaan!$B$5,Pemetaan!$B$6) -> 5 | G8: =F8+2+D8 -> 7 | H8: =Pemetaan!$B$2+E8 -> 11 | I8: =INDEX(Laporan!$A$1:$AZ$300,G8,1) -> Water Treatment | J8: =INDEX(Laporan!$A$1:$AZ$300,G8,2) -> 330 ml | K8: =INDEX(Laporan!$A$1:$AZ$300,G8,3) -> Shift 1 | L8: =INDEX(Laporan!$A$1:$AZ$300,G8,4) -> 1 | M8: =DATE(Pemetaan!$B$1,VALUE(RIGHT(INDEX(Laporan!$A$1:$AZ$300,F8+1,H8),2)),VALUE(LEFT(INDEX(Laporan!$A$1:$AZ$300,F8+1,H8),2))) -> 46091 | N8: =INDEX(Laporan!$A$1:$AZ$300,G8,H8) -> 2948 | O8: =IF(N8="","",IFERROR(VALUE(SUBSTITUTE(SUBSTITUTE(N8," btl",""),".","")),"")) -> 2948 | P8: =IF(B8="PRODUKSI","produced","reject") -> produced
A9: 8 | B9: =IF(A9<=36*25,"PRODUKSI","REJECT") -> PRODUKSI | C9: =MOD(A9-1,Pemetaan!$B$3*Pemetaan!$B$4) -> 7 | D9: =INT(C9/Pemetaan!$B$4) -> 0 | E9: =MOD(C9,Pemetaan!$B$4) -> 7 | F9: =IF(B9="PRODUKSI",Pemetaan!$B$5,Pemetaan!$B$6) -> 5 | G9: =F9+2+D9 -> 7 | H9: =Pemetaan!$B$2+E9 -> 12 | I9: =INDEX(Laporan!$A$1:$AZ$300,G9,1) -> Water Treatment | J9: =INDEX(Laporan!$A$1:$AZ$300,G9,2) -> 330 ml | K9: =INDEX(Laporan!$A$1:$AZ$300,G9,3) -> Shift 1 | L9: =INDEX(Laporan!$A$1:$AZ$300,G9,4) -> 1 | M9: =DATE(Pemetaan!$B$1,VALUE(RIGHT(INDEX(Laporan!$A$1:$AZ$300,F9+1,H9),2)),VALUE(LEFT(INDEX(Laporan!$A$1:$AZ$300,F9+1,H9),2))) -> 46092 | N9: =INDEX(Laporan!$A$1:$AZ$300,G9,H9) -> 3572 | O9: =IF(N9="","",IFERROR(VALUE(SUBSTITUTE(SUBSTITUTE(N9," btl",""),".","")),"")) -> 3572 | P9: =IF(B9="PRODUKSI","produced","reject") -> produced
A10: 9 | B10: =IF(A10<=36*25,"PRODUKSI","REJECT") -> PRODUKSI | C10: =MOD(A10-1,Pemetaan!$B$3*Pemetaan!$B$4) -> 8 | D10: =INT(C10/Pemetaan!$B$4) -> 0 | E10: =MOD(C10,Pemetaan!$B$4) -> 8 | F10: =IF(B10="PRODUKSI",Pemetaan!$B$5,Pemetaan!$B$6) -> 5 | G10: =F10+2+D10 -> 7 | H10: =Pemetaan!$B$2+E10 -> 13 | I10: =INDEX(Laporan!$A$1:$AZ$300,G10,1) -> Water Treatment | J10: =INDEX(Laporan!$A$1:$AZ$300,G10,2) -> 330 ml | K10: =INDEX(Laporan!$A$1:$AZ$300,G10,3) -> Shift 1 | L10: =INDEX(Laporan!$A$1:$AZ$300,G10,4) -> 1 | M10: =DATE(Pemetaan!$B$1,VALUE(RIGHT(INDEX(Laporan!$A$1:$AZ$300,F10+1,H10),2)),VALUE(LEFT(INDEX(Laporan!$A$1:$AZ$300,F10+1,H10),2))) -> 46093 | N10: =INDEX(Laporan!$A$1:$AZ$300,G10,H10) -> 3012 | O10: =IF(N10="","",IFERROR(VALUE(SUBSTITUTE(SUBSTITUTE(N10," btl",""),".","")),"")) -> 3012 | P10: =IF(B10="PRODUKSI","produced","reject") -> produced
A11: 10 | B11: =IF(A11<=36*25,"PRODUKSI","REJECT") -> PRODUKSI | C11: =MOD(A11-1,Pemetaan!$B$3*Pemetaan!$B$4) -> 9 | D11: =INT(C11/Pemetaan!$B$4) -> 0 | E11: =MOD(C11,Pemetaan!$B$4) -> 9 | F11: =IF(B11="PRODUKSI",Pemetaan!$B$5,Pemetaan!$B$6) -> 5 | G11: =F11+2+D11 -> 7 | H11: =Pemetaan!$B$2+E11 -> 14 | I11: =INDEX(Laporan!$A$1:$AZ$300,G11,1) -> Water Treatment | J11: =INDEX(Laporan!$A$1:$AZ$300,G11,2) -> 330 ml | K11: =INDEX(Laporan!$A$1:$AZ$300,G11,3) -> Shift 1 | L11: =INDEX(Laporan!$A$1:$AZ$300,G11,4) -> 1 | M11: =DATE(Pemetaan!$B$1,VALUE(RIGHT(INDEX(Laporan!$A$1:$AZ$300,F11+1,H11),2)),VALUE(LEFT(INDEX(Laporan!$A$1:$AZ$300,F11+1,H11),2))) -> 46094 | N11: =INDEX(Laporan!$A$1:$AZ$300,G11,H11) -> 3042 | O11: =IF(N11="","",IFERROR(VALUE(SUBSTITUTE(SUBSTITUTE(N11," btl",""),".","")),"")) -> 3042 | P11: =IF(B11="PRODUKSI","produced","reject") -> produced
A12: 11 | B12: =IF(A12<=36*25,"PRODUKSI","REJECT") -> PRODUKSI | C12: =MOD(A12-1,Pemetaan!$B$3*Pemetaan!$B$4) -> 10 | D12: =INT(C12/Pemetaan!$B$4) -> 0 | E12: =MOD(C12,Pemetaan!$B$4) -> 10 | F12: =IF(B12="PRODUKSI",Pemetaan!$B$5,Pemetaan!$B$6) -> 5 | G12: =F12+2+D12 -> 7 | H12: =Pemetaan!$B$2+E12 -> 15 | I12: =INDEX(Laporan!$A$1:$AZ$300,G12,1) -> Water Treatment | J12: =INDEX(Laporan!$A$1:$AZ$300,G12,2) -> 330 ml | K12: =INDEX(Laporan!$A$1:$AZ$300,G12,3) -> Shift 1 | L12: =INDEX(Laporan!$A$1:$AZ$300,G12,4) -> 1 | M12: =DATE(Pemetaan!$B$1,VALUE(RIGHT(INDEX(Laporan!$A$1:$AZ$300,F12+1,H12),2)),VALUE(LEFT(INDEX(Laporan!$A$1:$AZ$300,F12+1,H12),2))) -> 46097 | N12: =INDEX(Laporan!$A$1:$AZ$300,G12,H12) -> 3186 | O12: =IF(N12="","",IFERROR(VALUE(SUBSTITUTE(SUBSTITUTE(N12," btl",""),".","")),"")) -> 3186 | P12: =IF(B12="PRODUKSI","produced","reject") -> produced
A13: 12 | B13: =IF(A13<=36*25,"PRODUKSI","REJECT") -> PRODUKSI | C13: =MOD(A13-1,Pemetaan!$B$3*Pemetaan!$B$4) -> 11 | D13: =INT(C13/Pemetaan!$B$4) -> 0 | E13: =MOD(C13,Pemetaan!$B$4) -> 11 | F13: =IF(B13="PRODUKSI",Pemetaan!$B$5,Pemetaan!$B$6) -> 5 | G13: =F13+2+D13 -> 7 | H13: =Pemetaan!$B$2+E13 -> 16 | I13: =INDEX(Laporan!$A$1:$AZ$300,G13,1) -> Water Treatment | J13: =INDEX(Laporan!$A$1:$AZ$300,G13,2) -> 330 ml | K13: =INDEX(Laporan!$A$1:$AZ$300,G13,3) -> Shift 1 | L13: =INDEX(Laporan!$A$1:$AZ$300,G13,4) -> 1 | M13: =DATE(Pemetaan!$B$1,VALUE(RIGHT(INDEX(Laporan!$A$1:$AZ$300,F13+1,H13),2)),VALUE(LEFT(INDEX(Laporan!$A$1:$AZ$300,F13+1,H13),2))) -> 46098 | N13: =INDEX(Laporan!$A$1:$AZ$300,G13,H13) -> 3080 | O13: =IF(N13="","",IFERROR(VALUE(SUBSTITUTE(SUBSTITUTE(N13," btl",""),".","")),"")) -> 3080 | P13: =IF(B13="PRODUKSI","produced","reject") -> produced
... A1801: 1800 | B1801: =IF(A1801<=36*25,"PRODUKSI","REJECT") -> REJECT | C1801: =MOD(A1801-1,Pemetaan!$B$3*Pemetaan!$B$4) -> 899 | D1801: =INT(C1801/Pemetaan!$B$4) -> 35 | E1801: =MOD(C1801,Pemetaan!$B$4) -> 24 | F1801: =IF(B1801="PRODUKSI",Pemetaan!$B$5,Pemetaan!$B$6) -> 46 | G1801: =F1801+2+D1801 -> 83 | H1801: =Pemetaan!$B$2+E1801 -> 29 | I1801: =INDEX(Laporan!$A$1:$AZ$300,G1801,1) -> Mixing | J1801: =INDEX(Laporan!$A$1:$AZ$300,G1801,2) -> 1,5 L | K1801: =INDEX(Laporan!$A$1:$AZ$300,G1801,3) -> Shift 2 | L1801: =INDEX(Laporan!$A$1:$AZ$300,G1801,4) -> 3 | M1801: =DATE(Pemetaan!$B$1,VALUE(RIGHT(INDEX(Laporan!$A$1:$AZ$300,F1801+1,H1801),2)),VALUE(LEFT(INDEX(Laporan!$A$1:$AZ$300,F1801+1,H1801),2))) -> 46115 | N1801: =INDEX(Laporan!$A$1:$AZ$300,G1801,H1801) -> 7 | O1801: =IF(N1801="","",IFERROR(VALUE(SUBSTITUTE(SUBSTITUTE(N1801," btl",""),".","")),"")) -> 7 | P1801: =IF(B1801="PRODUKSI","produced","reject") -> reject
